Workbook

Sheet Dashboard
A1: HOME FEST | Painel Financeiro 3.0
A3: Modelo consolidado com base nas planilhas enviadas, já em padrão Brasil, com custos reais/estimados, simulador, fluxo de caixa e painel executivo.
B5: Receita Contratada | E5: Custo dos Eventos | H5: Lucro Bruto | K5: Margem Bruta
B6: =SUM(Eventos_Receitas!F6:F13) | E6: =SUM(Eventos_Receitas!G6:G13) | H6: =SUM(Eventos_Receitas!H6:H13) | K6: =IF(B6=0,0,H6/B6)
B9: Despesas Fixas | E9: Ativos / Investimentos | H9: Caixa Projetado | K9: Eventos Vendidos
B10: =SUM(Despesas_Fixas!E6:E34) | E10: =SUM(Investimentos_Ativos!E6:E81) | H10: =Fluxo_Caixa_Mensal!H11 | K10: =COUNTA(Eventos_Receitas!A6:A13)
A22: Tipo | B22: Receita
A23: Infantil | B23: 52728

Sheet Eventos_Receitas
A1: Eventos | Receitas, Custos e Margem
A3: Custos reais foram usados quando havia planilha específica do evento. Nos demais, a planilha usa a base genérica por faixa de convidados.
A5: ID | B5: Cliente | C5: Tipo | D5: Data Fechamento | E5: Data Evento | F5: Receita | G5: Custo Evento | H5: Lucro Bruto | I5: Margem | J5: Recebido | K5: Saldo | L5: Base de Custo | M5: Observações
A6: 1 | B6: Mateus | C6: Infantil | D6: 45982 | E6: 45990 | F6: 6220 | G6: 3733.06 | H6: =F6-G6 | I6: =IF(F6=0,0,H6/F6) | J6: 6220 | K6: 0 | L6: Estimado
A7: 2 | B7: Ronaldo | C7: Infantil | D7: 46009 | E7: 46011 | F7: 9990 | G7: 6390.08 | H7: =F7-G7 | I7: =IF(F7=0,0,H7/F7) | J7: 9990 | K7: 0 | L7: Estimado
A8: 3 | B8: Shirley | C8: Infantil | D8: 46006 | E8: 46010 | F8: 1749 | G8: 3223.8 | H8: =F8-G8 | I8: =IF(F8=0,0,H8/F8) | J8: 1749 | K8: 0 | L8: Estimado
A9: 4 | B9: Laissa | C9: Infantil | D9: 46043 | E9: 46075 | F9: 5950 | G9: 4475.51 | H9: =F9-G9 | I9: =IF(F9=0,0,H9/F9) | J9: 5950 | K9: 0 | L9: Real
A10: 5 | B10: Aline | C10: Infantil | D10: 46043 | E10: 46088 | F10: 8579 | G10: 6926.11 | H10: =F10-G10 | I10: =IF(F10=0,0,H10/F10) | J10: 8579 | K10: 0 | L10: Real
A11: 6 | B11: Luciana | C11: Infantil | D11: 46080 | E11: 46095 | F11: 6640 | G11: 4600.89 | H11: =F11-G11 | I11: =IF(F11=0,0,H11/F11) | J11: 6640 | K11: 0 | L11: Real
A12: 7 | B12: Flávia | C12: Infantil | D12: 46076 | E12: 46102 | F12: 5450 | G12: 5162 | H12: =F12-G12 | I12: =IF(F12=0,0,H12/F12) | J12: 5450 | K12: 0 | L12: Real
A13: 8 | B13: Bruno | C13: Infantil | D13: 46084 | E13: 46109 | F13: 8150 | G13: 3767.79 | H13: =F13-G13 | I13: =IF(F13=0,0,H13/F13) | J13: 8150 | K13: 0 | L13: Estimado
E14: Totais | F14: =SUM(F6:F13) | G14: =SUM(G6:G13) | H14: =SUM(H6:H13) | I14: =IF(F14=0,0,H14/F14) | J14: =SUM(J6:J13) | K14: =SUM(K6:K13)

Sheet Despesas_Fixas
A1: Despesas Fixas | Base Real
A3: Lançamentos importados da planilha financeira enviada. Subtotais originais foram removidos para evitar dupla contagem.
A5: ID | B5: Mês Ref. | C5: Categoria | D5: Descrição | E5: Fornecedor | F5: Valor
A6: 1 | B6: Novembro 2025 | C6: Fixa | D6: Telefone | E6: Vivo | F6: 39.9
A7: 2 | B7: Novembro 2025 | C7: Fixa | D7: Canva | E7: Canva | F7: 35
A8: 3 | B8: Novembro 2025 | C8: Fixa | D8: Chat Gpt | E8: Chat Gpt | F8: 98
A9: 4 | B9: Novembro 2025 | C9: Pró-labore | D9: Retirada Tati | E9: Sócio | F9: 2000
A10: 5 | B10: Dezembro 2025 | C10: Fixa | D10: Taxa Das | E10: CNPJ | F10: 85.45
A11: 6 | B11: Dezembro 2025 | C11: Fixa | D11: Telefone | E11: Vivo | F11: 39.9
A12: 7 | B12: Dezembro 2025 | C12: Fixa | D12: Canva | E12: Canva | F12: 35
A13: 8 | B13: Dezembro 2025 | C13: Fixa | D13: Chat Gpt | E13: Chat Gpt | F13: 98
A14: 9 | B14: Dezembro 2025 | C14: Pró-labore | D14: Retirada Tati | E14: Sócio | F14: 2000
A15: 10 | B15: Janeiro 2026 | C15: Fixa | D15: Taxa Das | E15: CNPJ | F15: 94.01
A16: 11 | B16: Janeiro 2026 | C16: Fixa | D16: Telefone | E16: Vivo | F16: 39.9
A17: 12 | B17: Janeiro 2026 | C17: Fixa | D17: Canva | E17: Canva | F17: 35
... A34: 29 | B34: Abril 2026 | C34: Pró-labore | D34: Retirada Tati | E34: Sócio | F34: 2000
E35: Total | F35: =SUM(F6:F34)

Sheet Investimentos_Ativos
A1: Ativos e Investimentos | Home Fest
A3: Base importada da planilha financeira. Onde o valor total não estava preenchido, o item foi mantido para conferência.
A5: ID | B5: Macro Grupo | C5: Item | D5: Quantidade | E5: Valor Total | F5: Status
A6: 1 | B6: Administrativo | C6: Notebook | D6: 1 | E6: 2500 | F6: Ok
A7: 2 | B7: Administrativo | C7: Impressora | D7: 1 | E7: 800 | F7: Ok
A8: 3 | B8: Administrativo | C8: Celular | D8: 1 | E8: 1000 | F8: Ok
A9: 4 | B9: Administrativo | C9: Chip para celular | D9: 1 | E9: 20 | F9: Ok
A10: 5 | B10: Administrativo | C10: Pasta arquivo | D10: 1 | E10: 39.9 | F10: Ok
A11: 6 | B11: Administrativo | C11: Papelaria (canetas, pastas, caderno, grampeador) | E11: 250 | F11: Ok
A12: 7 | B12: Administrativo | C12: Fritadeira | D12: 1 | E12: 2200 | F12: Ok
A13: 8 | B13: Administrativo | C13: Forno Elétrico | D13: 1 | E13: 800 | F13: Ok
A14: 9 | B14: Administrativo | C14: Carrinho de transporte | D14: 1 | E14: 239 | F14: Ok
A15: 10 | B15: Administrativo | C15: Uniforme Blusas e Avental | E15: 1818.8 | F15: Ok
A16: 11 | B16: Administrativo | C16: Adesivos para caixas Grafica | E16: 179.7 | F16: Ok
A17: 12 | B17: Administrativo | C17: Adesivos para copo milk shake | E17: 620 | F17: Ok
A18: 13 | B18: Administrativo | C18: Caixas organizadoras grandes | D18: 5 | E18: 500 | F18: Ok
A19: 14 | B19: Administrativo | C19: Caixas organizadoras pequenas | D19: 3 | E19: 180 | F19: Ok
A20: 15 | B20: Administrativo | C20: Ventiladores portáteis | D20: 2 | E20: 196 | F20: Ok
A21: 16 | B21: Administrativo | C21: Pilhas | D21: 4 | E21: 4 | F21: Ok
A22: 17 | B22: Administrativo | C22: Fogão | D22: 1 | E22: 0 | F22: Conferir
A23: 18 | B23: Administrativo | C23: Liquidificador | D23: 1 | E23: 239 | F23: Ok
A24: 19 | B24: Administrativo | C24: Maquina de cartão | D24: 1 | E24: 149 | F24: Ok
A25: 20 | B25: Administrativo | C25: Frigideira antiaderente | D25: 1 | E25: 89 | F25: Ok
A26: 21 | B26: Administrativo | C26: Panelas de ferro | D26: 3 | E26: 450 | F26: Ok
A27: 22 | B27: Administrativo | C27: Extensão | D27: 1 | E27: 0 | F27: Conferir
A28: 23 | B28: Administrativo | C28: Fita adesiva | D28: 1 | E28: 0 | F28: Conferir
A29: 24 | B29: Administrativo | C29: Adaptador de tomadas | D29: 3 | E29: 30 | F29: Ok
... A31: 26 | B31: Administrativo | C31: Cooler | D31: 2 | E31: 278 | F31: Ok
A32: 27 | B32: Administrativo | C32: Total Material | E32: 12660.4 | F32: Ok
A33: 28 | B33: Administrativo | C33: Total Cozinha | E33: 564 | F33: Ok
A34: 29 | B34: Administrativo | C34: Total Decoração | E34: 1290.76 | F34: Ok
A35: 30 | B35: Administrativo | C35: Total Investimento | E35: 14515.16 | F35: Ok
A36: 31 | B36: Cozinha/Operação | C36: Bacias | E36: 0 | F36: Conferir
A37: 32 | B37: Cozinha/Operação | C37: Bandeja retangular | D37: 1 | E37: 0 | F37: Conferir
A38: 33 | B38: Cozinha/Operação | C38: Bandejas grandes | D38: 1 | E38: 0 | F38: Conferir
A39: 34 | B39: Cozinha/Operação | C39: Bandejas pequenas | D39: 3 | E39: 0 | F39: Conferir
A40: 35 | B40: Cozinha/Operação | C40: Bandejas brancas retas | D40: 2 | E40: 0 | F40: Conferir
A41: 36 | B41: Cozinha/Operação | C41: Boleira branca | D41: 1 | E41: 0 | F41: Conferir
A42: 37 | B42: Cozinha/Operação | C42: Boleira transparente | D42: 2 | E42: 0 | F42: Conferir
A43: 38 | B43: Cozinha/Operação | C43: Bowls transparentes | D43: 3 | E43: 0 | F43: Conferir
...

Sheet Catalogo_Pacotes
A1: Catálogo de Pacotes e Bases de Custo
A3: Esta aba serve como inteligência de precificação. O simulador busca os custos base daqui.
A5: ID | B5: Tipo | C5: Pessoas | D5: Custo Base | E5: Preço Referência | F5: Margem Ref. | G5: Custo por Pessoa
A6: 1 | B6: Brunch | C6: 30 | D6: 2277.47 | E6: 3099.5 | F6: 0.26521374 | G6: 75.915667
A7: 2 | B7: Café | C7: 50 | D7: 2555.52 | E7: 0 | F7: 0.3 | G7: 51.1104
A8: 3 | B8: Infantil | C8: 20 | D8: 3223.8 | E8: 0 | F8: 0.2 | G8: 161.19
A9: 4 | B9: Infantil | C9: 30 | D9: 3655.53 | E9: 0 | F9: 0.3 | G9: 121.851
A10: 5 | B10: Infantil | C10: 40 | D10: 3733.06 | E10: 4470 | F10: 0.16486353 | G10: 93.3265
A11: 6 | B11: Infantil | C11: 50 | D11: 3767.79 | E11: 5950 | F11: 0.36675798 | G11: 75.3558
A12: 7 | B12: Infantil | C12: 60 | D12: 4904.22 | E12: 6380.5 | F12: 0.23137372 | G12: 81.737
A13: 8 | B13: Infantil | C13: 70 | D13: 4870.3 | E13: 8399.5 | F13: 0.42016787 | G13: 69.575714
A14: 9 | B14: Infantil | C14: 80 | D14: 6390.08 | E14: 9990 | F14: 0.36035235 | G14: 79.876
A15: 10 | B15: Infantil | C15: 100 | D15: 7411.28 | E15: 10200 | F15: 0.27340392 | G15: 74.1128
A16: 11 | B16: Infantil | C16: 150 | D16: 10238.43 | E16: 13799 | F16: 0.25803102 | G16: 68.2562

Sheet Fluxo_Caixa_Mensal
A1: Fluxo de Caixa Mensal
A3: Entradas por mês de fechamento + custos dos eventos pelo mês de execução + despesas fixas pelo mês de referência.
A5: Mês | B5: Receita Fechada | C5: Recebido | D5: Custos Eventos | E5: Despesas Fixas | F5: Investimentos | G5: Resultado do Mês | H5: Saldo Acumulado
A6: 45962 | B6: =SUMPRODUCT((MONTH(Eventos_Receitas!$D$6:$D$13)=MONTH(A6))*(YEAR(Eventos_Receitas!$D$6:$D$13)=YEAR(A6))*Eventos_Receitas!$F$6:$F$13) | C6: =SUMPRODUCT((MONTH(Eventos_Receitas!$D$6:$D$13)=MONTH(A6))*(YEAR(Eventos_Receitas!$D$6:$D$13)=YEAR(A6))*Eventos_Receitas!$J$6:$J$13) | D6: =SUMPRODUCT((MONTH(Eventos_Receitas!$E$6:$E$13)=MONTH(A6))*(YEAR(Eventos_Receitas!$E$6:$E$13)=YEAR(A6))*Eventos_Receitas!$G$6:$G$13) | E6: =SUMIF(Despesas_Fixas!$B$6:$B$34,"Novembro 2025*",Despesas_Fixas!$F$6:$F$34) | F6: 23280 | G6: =C6-D6-E6-F6 | H6: =G6
A7: 45992 | B7: =SUMPRODUCT((MONTH(Eventos_Receitas!$D$6:$D$13)=MONTH(A7))*(YEAR(Eventos_Receitas!$D$6:$D$13)=YEAR(A7))*Eventos_Receitas!$F$6:$F$13) | C7: =SUMPRODUCT((MONTH(Eventos_Receitas!$D$6:$D$13)=MONTH(A7))*(YEAR(Eventos_Receitas!$D$6:$D$13)=YEAR(A7))*Eventos_Receitas!$J$6:$J$13) | D7: =SUMPRODUCT((MONTH(Eventos_Receitas!$E$6:$E$13)=MONTH(A7))*(YEAR(Eventos_Receitas!$E$6:$E$13)=YEAR(A7))*Eventos_Receitas!$G$6:$G$13) | E7: =SUMIF(Despesas_Fixas!$B$6:$B$34,"Dezembro 2025*",Despesas_Fixas!$F$6:$F$34) | F7: 0 | G7: =C7-D7-E7-F7 | H7: =H6+G7
A8: 46023 | B8: =SUMPRODUCT((MONTH(Eventos_Receitas!$D$6:$D$13)=MONTH(A8))*(YEAR(Eventos_Receitas!$D$6:$D$13)=YEAR(A8))*Eventos_Receitas!$F$6:$F$13) | C8: =SUMPRODUCT((MONTH(Eventos_Receitas!$D$6:$D$13)=MONTH(A8))*(YEAR(Eventos_Receitas!$D$6:$D$13)=YEAR(A8))*Eventos_Receitas!$J$6:$J$13) | D8: =SUMPRODUCT((MONTH(Eventos_Receitas!$E$6:$E$13)=MONTH(A8))*(YEAR(Eventos_Receitas!$E$6:$E$13)=YEAR(A8))*Eventos_Receitas!$G$6:$G$13) | E8: =SUMIF(Despesas_Fixas!$B$6:$B$34,"Janeiro 2026*",Despesas_Fixas!$F$6:$F$34) | F8: 0 | G8: =C8-D8-E8-F8 | H8: =H7+G8
A9: 46054 | B9: =SUMPRODUCT((MONTH(Eventos_Receitas!$D$6:$D$13)=MONTH(A9))*(YEAR(Eventos_Receitas!$D$6:$D$13)=YEAR(A9))*Eventos_Receitas!$F$6:$F$13) | C9: =SUMPRODUCT((MONTH(Eventos_Receitas!$D$6:$D$13)=MONTH(A9))*(YEAR(Eventos_Receitas!$D$6:$D$13)=YEAR(A9))*Eventos_Receitas!$J$6:$J$13) | D9: =SUMPRODUCT((MONTH(Eventos_Receitas!$E$6:$E$13)=MONTH(A9))*(YEAR(Eventos_Receitas!$E$6:$E$13)=YEAR(A9))*Eventos_Receitas!$G$6:$G$13) | E9: =SUMIF(Despesas_Fixas!$B$6:$B$34,"Fevereiro 2026*",Despesas_Fixas!$F$6:$F$34) | F9: 0 | G9: =C9-D9-E9-F9 | H9: =H8+G9
A10: 46082 | B10: =SUMPRODUCT((MONTH(Eventos_Receitas!$D$6:$D$13)=MONTH(A10))*(YEAR(Eventos_Receitas!$D$6:$D$13)=YEAR(A10))*Eventos_Receitas!$F$6:$F$13) | C10: =SUMPRODUCT((MONTH(Eventos_Receitas!$D$6:$D$13)=MONTH(A10))*(YEAR(Eventos_Receitas!$D$6:$D$13)=YEAR(A10))*Eventos_Receitas!$J$6:$J$13) | D10: =SUMPRODUCT((MONTH(Eventos_Receitas!$E$6:$E$13)=MONTH(A10))*(YEAR(Eventos_Receitas!$E$6:$E$13)=YEAR(A10))*Eventos_Receitas!$G$6:$G$13) | E10: =SUMIF(Despesas_Fixas!$B$6:$B$34,"Março 2026*",Despesas_Fixas!$F$6:$F$34) | F10: 0 | G10: =C10-D10-E10-F10 | H10: =H9+G10
A11: 46113 | B11: =SUMPRODUCT((MONTH(Eventos_Receitas!$D$6:$D$13)=MONTH(A11))*(YEAR(Eventos_Receitas!$D$6:$D$13)=YEAR(A11))*Eventos_Receitas!$F$6:$F$13) | C11: =SUMPRODUCT((MONTH(Eventos_Receitas!$D$6:$D$13)=MONTH(A11))*(YEAR(Eventos_Receitas!$D$6:$D$13)=YEAR(A11))*Eventos_Receitas!$J$6:$J$13) | D11: =SUMPRODUCT((MONTH(Eventos_Receitas!$E$6:$E$13)=MONTH(A11))*(YEAR(Eventos_Receitas!$E$6:$E$13)=YEAR(A11))*Eventos_Receitas!$G$6:$G$13) | E11: =SUMIF(Despesas_Fixas!$B$6:$B$34,"Abril 2026*",Despesas_Fixas!$F$6:$F$34) | F11: 0 | G11: =C11-D11-E11-F11 | H11: =H10+G11
A12: Total | B12: =SUM(B6:B11) | C12: =SUM(C6:C11) | D12: =SUM(D6:D11) | E12: =SUM(E6:E11) | F12: =SUM(F6:F11) | G12: =SUM(G6:G11) | H12: =H11

Sheet Simulador_Evento
A1: Simulador de Evento | Precificação
A3: Preencha apenas as células azuis. O modelo busca custo base no catálogo, calcula proposta, entrada, saldo e lucro.
A6: Tipo do pacote | B6: Infantil | E6: Saídas do modelo
A7: Pessoas | B7: 50 | E7: Custo base localizado | F7: =SUMIFS(Catalogo_Pacotes!$D$6:$D$16,Catalogo_Pacotes!$B$6:$B$16,$B$6,Catalogo_Pacotes!$C$6:$C$16,$B$7)
A8: Margem desejada | B8: 0.3 | E8: Preço bruto sugerido | F8: =IF(B8>=1,0,ROUND(F7/(1-B8),2))
A9: Extras / Acréscimos | B9: 0 | E9: Preço final proposto | F9: =ROUND(F8+B9-B10,2)
A10: Desconto concedido | B10: 0 | E10: Lucro estimado | F10: =ROUND(F9-F7,2)
A11: Entrada (%) | B11: 0.5 | E11: Margem final | F11: =IF(F9=0,0,F10/F9)
E12: Entrada sugerida | F12: =ROUND(F9*B11,2)
E13: Saldo final | F13: =ROUND(F9-F12,2)

Sheet Conferencia
A1: Pontos de Conferência
A3: Itens que merecem validação manual para deixar a base 100% fechada.
A5: Tema | B5: Item | C5: Prioridade | D5: Ação | E5: Impacto | F5: Observação
A6: Receitas | B6: Cliente Ronaldo/Leonardo | C6: Alta | D6: Confirmar nome correto | E6: Médio | F6: A planilha financeira traz "Leonardo", enquanto o caderno vermelho indicava "Ronaldo".
A7: Receitas | B7: Cliente Bruno/Renan | C7: Alta | D7: Confirmar nome correto | E7: Médio | F7: A planilha financeira traz "Renan", enquanto o caderno vermelho indicava "Bruno".
A8: Custos | B8: Evento Shirley 20 pessoas | C8: Alta | D8: Revisar custo real | E8: Alto | F8: A base genérica de 20 pessoas gerou margem negativa; pode haver pacote simplificado ou dados faltantes.
A9: Ativos | B9: Itens com valor zero | C9: Média | D9: Preencher valor | E9: Médio | F9: Mantidos no inventário para não perder estrutura.
A10: Caixa | B10: Recebimentos futuros | C10: Média | D10: Atualizar coluna recebido/saldo | E10: Alto | F10: O modelo considerou tudo recebido até você lançar parcelas em aberto.
